Workbook

Sheet Sheet5
A3: Row Labels | B3: Sum of Amount
A4: 2012 | B4: -667051.46
A5: 2013 | B5: -315064.99
A6: 2014 | B6: -383809.58
A7: 2015 | B7: -635753.28
A8: 2016 | B8: -585556.32
A9: 2017 | B9: -932299.65
A10: 2018 | B10: -1003099.7
A11: 2019 | B11: -787099.83
A12: 2020 | B12: -861234.78
A13: 2021 | B13: -505258.08
A14: 2022 | B14: -1190742.8
A15: 2023 | B15: -568545.9
A16: 2024 | B16: -483693.96
A17: Grand Total | B17: -8919210.4

Sheet Sheet6
A3: Row Labels | B3: Count of Year
A4: 2002 | B4: 137
A5: 2003 | B5: 113
A6: 2004 | B6: 196
A7: 2005 | B7: 150
A8: 2006 | B8: 249
A9: 2007 | B9: 106
A10: 2008 | B10: 73
A11: 2009 | B11: 30
A12: 2010 | B12: 303
A13: 2011 | B13: 166
A14: 2012 | B14: 1045
A15: 2013 | B15: 690
... A26: 2024 | B26: 427
A27: Grand Total | B27: 13284

Sheet Report
A1: Itemized Categories - All Dates
A3: 8/12/1996 through 2/1/2025 (Cash Basis)
B5: Date | C5: Account | D5: Num | E5: Description | F5: Memo | G5: Tag | H5: Clr | I5: Amount | J5: Amount | K5: Amount | O5: Amount | P5: Year
B8: EXPENSES | I8: -9240773.5 | J8: -9240773.5 | K8: -9240773.5
B9: TT Renovations | I9: -9240773.5 | J9: -9240773.5 | K9: -9240773.5
B10: TT Renovations:4039 Central | I10: -7538.26 | J10: -7538.26 | K10: -7538.26
B11: 37284 | C11: Marvel MC | D11: DC | E11: Lowe's | H11: R | I11: -25.05 | J11: -25.05 | K11: -25.05
B12: 37286 | C12: Cash | E12: Roof Repair | I12: 800 | K12: 800
B13: 37294 | C13: Marvel MC | D13: DC | E13: BMV | F13: truck plates - pay all due to inspection | H13: R | I13: -190.75 | J13: -190.75 | K13: -190.75
B14: 37305 | C14: Marvel MC | E14: Dave's Trucking | F14: dumpster | H14: R | I14: -270 | J14: -270 | K14: -270 | M14: Row Labels | N14: Count of Tag | P14: {=YEAR(B14:B14342)} -> 2002 | R14: Row Labels | T14: Row Labels | U14: Count of 2012 | W14: Row Labels | X14: Sum of Amount
B15: TT Renovations:47th St. | I15: 63871.02 | J15: =SUM(J16:J69) -> -45885.09 | K15: 63871.02 | M15: ADDITIONAL WORK | N15: 9 | P15: #VALUE! | R15: 1900 | T15: 1900 | U15: 786 | W15: 1900 | X15: -215859.32
A16: TT Renovations:47th St. | B16: 37307 | C16: Marvel MC | D16: DC | E16: Lowe's | H16: R | I16: -155.04 | J16: -155.04 | K16: -155.04 | M16: APPLIANCE INSTALL | N16: 96 | P16: 2002 | R16: 2002 | T16: 2002 | U16: 137 | W16: 2002 | X16: 16669.82
A17: TT Renovations:47th St. | B17: 37308 | C17: Marvel MC | D17: DC | E17: Lowe's | H17: R | I17: -30.2 | J17: -30.2 | K17: -30.2 | M17: APPLIANCES | N17: 14 | P17: 2002 | R17: 2003 | T17: 2003 | U17: 113 | W17: 2003 | X17: -19618.68
A18: TT Renovations:47th St. | B18: 37308 | C18: Marvel MC | D18: DC | E18: Lowe's | H18: R | I18: -534.41 | J18: -534.41 | K18: -534.41 | M18: ARCHITECT | N18: 5 | P18: 2002 | R18: 2004 | T18: 2004 | U18: 196 | W18: 2004 | X18: -22174.06
A19: TT Renovations:47th St. | B19: 37308 | C19: Marvel MC | E19: Reese Kitchens | H19: R | I19: -744.45 | J19: -744.45 | K19: -744.45 | M19: ASBESTOS REMOVAL | N19: 17 | P19: 2002 | R19: 2005 | T19: 2005 | U19: 150 | W19: 2005 | X19: 7101.03
A20: TT Renovations:47th St. | B20: 37309 | C20: Marvel MC | D20: DC | E20: Lowe's | H20: R | I20: -5.4 | J20: -5.4 | K20: -5.4 | M20: ASPHALT | N20: 2 | P20: 2002 | R20: 2006 | T20: 2006 | U20: 249 | W20: 2006 | X20: -11272.94
A21: TT Renovations:47th St. | B21: 37315 | C21: Marvel MC | D21: DC | E21: Lowe's | H21: R | I21: -110.9 | J21: -110.9 | K21: -110.9 | M21: BACKSPLASH | N21: 19 | P21: 2002 | R21: 2007 | T21: 2007 | U21: 106 | W21: 2007 | X21: 85972.11
A22: TT Renovations:47th St. | B22: 37316 | C22: Marvel MC | D22: DC | E22: Lowe's | H22: R | I22: -47.22 | J22: -47.22 | K22: -47.22 | M22: BASEMENT WATERPROOFING | N22: 4 | P22: 2002 | R22: 2008 | T22: 2008 | U22: 73 | W22: 2008 | X22: -31696.21
A23: TT Renovations:47th St. | B23: 37317 | C23: Huntington Checking-Ralston Checking | D23: DEP S | E23: Allied Services | H23: R | I23: 976.04 | K23: 976.04 | M23: CABINET BUILD | N23: 318 | P23: 2002 | R23: 2009 | T23: 2009 | U23: 30 | W23: 2009 | X23: 3690.25
A24: TT Renovations:47th St. | B24: 37317 | C24: Huntington Checking-Ralston Checking | D24: 1 | E24: Theresa Tetrault | F24: drywall/travis | H24: R | I24: -250 | J24: -250 | K24: -250 | M24: CABINETRY | N24: 32 | P24: 2002 | R24: 2010 | T24: 2010 | U24: 303 | W24: 2010 | X24: -35353.34
A25: TT Renovations:47th St. | B25: 37317 | C25: Huntington Checking-Ralston Checking | D25: 3 | E25: Theresa Tetrault | F25: truck ins/gas/lowe's/travis | H25: R | I25: -202.31 | J25: -202.31 | K25: -202.31 | M25: CABINETRY INSTALL | N25: 126 | P25: 2002 | R25: 2011 | T25: 2011 | U25: 166 | W25: 2011 | X25: -18019.41
A26: TT Renovations:47th St. | B26: 37317 | C26: Cash | E26: Gerry Sanders | F26: 1/2 drywall | I26: -315 | J26: -315 | K26: -315 | M26: CARPENTRY | N26: 64 | P26: 2002 | R26: 2012 | T26: 2012 | U26: 1044 | W26: 2012 | X26: -667051.46
A27: TT Renovations:47th St. | B27: 37319 | C27: Marvel MC | D27: DC | E27: Lowe's | H27: R | I27: -98.54 | J27: -98.54 | K27: -98.54 | M27: CARPET | N27: 10 | P27: 2002 | R27: 2013 | T27: 2013 | U27: 690 | W27: 2013 | X27: -315064.99
A28: TT Renovations:47th St. | B28: 37320 | C28: Marvel MC | D28: DC | E28: Lowe's | H28: R | I28: -8.06 | J28: -8.06 | K28: -8.06 | M28: CLEANUP | N28: 9 | P28: 2002 | R28: 2014 | T28: 2014 | U28: 976 | W28: 2014 | X28: -383809.58
A29: TT Renovations:47th St. | B29: 37320 | C29: Marvel MC | D29: DC | E29: Lowe's | H29: R | I29: -23.15 | J29: -23.15 | K29: -23.15 | M29: CLOSET SHELVING | N29: 9 | P29: 2002 | R29: 2015 | T29: 2015 | U29: 1392 | W29: 2015 | X29: -635753.28
A30: TT Renovations:47th St. | B30: 37321 | C30: Marvel MC | D30: DC | E30: Lowe's | H30: R | I30: -33.5 | J30: -33.5 | K30: -33.5 | M30: CONCRETE | N30: 87 | P30: 2002 | R30: 2016 | T30: 2016 | U30: 1062 | W30: 2016 | X30: -585556.32
A31: TT Renovations:47th St. | B31: 37322 | C31: Marvel MC | D31: DC | E31: Lowe's | H31: R | I31: -89.79 | J31: -89.79 | K31: -89.79 | M31: COUNTERTOPS | N31: 92 | P31: 2002 | R31: 2017 | T31: 2017 | U31: 1199 | W31: 2017 | X31: -932299.65
A32: TT Renovations:47th St. | B32: 37323 | C32: Marvel MC | D32: DC | E32: Lowe's | H32: R | I32: -139.56 | J32: -139.56 | K32: -139.56 | M32: DECK | N32: 67 | P32: 2002 | R32: 2018 | T32: 2018 | U32: 1220 | W32: 2018 | X32: -1003099.7
A33: TT Renovations:47th St. | B33: 37324 | C33: Marvel MC | D33: DC | E33: Lowe's | H33: R | I33: -87.13 | J33: -87.13 | K33: -87.13 | M33: DECK LABOR | N33: 5 | P33: 2002 | R33: 2019 | T33: 2019 | U33: 1385 | W33: 2019 | X33: -787099.83
A34: TT Renovations:47th St. | B34: 37326 | C34: Marvel MC | E34: Reese Kitchens | H34: R | I34: -744.45 | J34: -744.45 | K34: -744.45 | M34: DELIVERY | N34: 10 | P34: 2002 | R34: 2020 | T34: 2020 | U34: 1057 | W34: 2020 | X34: -861234.78
A35: TT Renovations:47th St. | B35: 37326 | C35: Marvel MC | D35: DC | E35: Lowe's | H35: R | I35: -15 | J35: -15 | K35: -15 | M35: DEMO | N35: 532 | P35: 2002 | R35: 2021 | T35: 2021 | U35: 373 | W35: 2021 | X35: -505258.08
A36: TT Renovations:47th St. | B36: 37326 | C36: Marvel MC | D36: DC | E36: Speedway | H36: R | I36: -17.65 | J36: -17.65 | K36: -17.65 | M36: DEMO:FRAMING | N36: 3 | P36: 2002 | R36: 2022 | T36: 2022 | U36: 487 | W36: 2022 | X36: -1190742.8
A37: TT Renovations:47th St. | B37: 37327 | C37: Huntington Checking-Ralston Checking | D37: 4 | E37: Bud Hindsley | F37: plumbing/travis | H37: R | I37: -697.21 | J37: -697.21 | K37: -697.21 | M37: DOORS | N37: 200 | P37: 2002 | R37: 2023 | T37: 2023 | U37: 448 | W37: 2023 | X37: -568545.9
A38: TT Renovations:47th St. | B38: 37327 | C38: Huntington Checking-Ralston Checking | D38: 5 | E38: Gerry Sanders | F38: painting/travis | H38: R | I38: -200 | J38: -200 | K38: -200 | M38: DRYWALL | N38: 350 | P38: 2002 | R38: 2024 | T38: 2024 | U38: 427 | W38: 2024 | X38: -483693.96
A39: TT Renovations:47th St. | B39: 37327 | C39: Marvel MC | E39: Dave's Trucking | H39: R | I39: -245 | J39: -245 | K39: -245 | M39: DUMP LABOR | N39: 62 | P39: 2002 | R39: 2025 | T39: 2025 | U39: 49 | W39: 2025 | X39: -55458.71
A40: TT Renovations:47th St. | B40: 37331 | C40: Huntington Checking-Ralston Checking | D40: 6 | E40: Bill York | F40: plumbing/travis | H40: R | I40: -80 | J40: -80 | K40: -80 | M40: DUMPSTER | N40: 445 | P40: 2002 | R40: #VALUE! | T40: #VALUE! | U40: 210 | W40: Grand Total | X40: -9215229.9
A41: TT Renovations:47th St. | B41: 37331 | C41: Huntington Checking-Ralston Checking | D41: 101 | E41: Bart Mousa | F41: tile/travis | H41: R | I41: -100 | J41: -100 | K41: -100 | M41: ELEC FINISH MATERIALS | N41: 243 | P41: 2002 | R41: Grand Total | T41: Grand Total | U41: 14328
A42: TT Renovations:47th St. | B42: 37340 | C42: Huntington Checking-Ralston Checking | D42: DEP | E42: Travis Tetrault | H42: R | I42: 780 | K42: 780 | M42: ELEC LABOR | N42: 92 | P42: 2002
A43: TT Renovations:47th St. | B43: 37341 | C43: Huntington Checking-Ralston Checking | D43: 105 | E43: James Warriner | F43: hardwoods/travis | H43: R | I43: -2360 | J43: -2360 | K43: -2360 | M43: ELEC ROUGH MATERIALS | N43: 161 | P43: 2002
A44: TT Renovations:47th St. | B44: 37343 | C44: Huntington Checking-Ralston Checking | D44: DC | E44: Lowe's | H44: R | I44: -17.64 | J44: -17.64 | K44: -17.64 | M44: ELECTRICAL EXTRAS | N44: 250 | P44: 2002
...

Sheet timeline
A1: Milestones | B1: 45689 | C1: 45696 | D1: 45703 | E1: 45710 | F1: 45717 | G1: 45724 | H1: 45731 | I1: 45738 | J1: 45745 | K1: 45752 | L1: 45759 | M1: 45766 | N1: 45773 | O1: 45780
A2: Phase 1
A3: Make Timeline
A4: Gather Data
A5: Data Cleanup
A6: Consolidate Data
A7: Phase 2
A8: Visualization
A9: Identify Trends
A10: Report Insights
A11: Phase 3
A12: Develop Website
A13: Mapping
... A17: Final Project

Sheet totals
A1: Date | B1: Original Payee | C1: Last Name | D1: Amount | E1: Address | F1: Zip Code | H1: Row Labels | I1: Count of Zip Code
A2: TT Renovations | B2: 4039 Central | C2: Central | D2: -7538.26 | E2: 4039 Central Ave. | F2: 46205 | H2: 46013 | I2: 1
A3: TT Renovations | B3: 47th St. | C3: 47th | D3: -56134.38 | E3: 326 E 47th St | F3: 46205 | H3: 46032 | I3: 3
A4: TT Renovations | B4: Beverly Olsen (Abelard Co.) | C4: Olsen | D4: -3200 | E4: 13295 Illinois St | F4: 46032 | H4: 46033 | I4: 7
A5: TT Renovations | B5: Aimee Kandrac | C5: Yockey | D5: -130530.43 | E5: =VLOOKUP(C5,addresses!B:C,2,FALSE) -> 5325 Central Ave. | F5: =VLOOKUP(C5,addresses!B:D,3,FALSE) -> 46220 | H5: 46037 | I5: 2
A6: TT Renovations | B6: Mary Ajamie | C6: Ajamie | D6: -13354.71 | E6: =VLOOKUP(C6,addresses!B:C,2,FALSE) -> 4521 Pennsylvania St. | F6: 46205 | H6: 46077 | I6: 2
A7: TT Renovations | B7: Allen | C7: Tunstall | D7: -4506.86 | E7: 5645 Ralston Ave. | F7: 46220 | H7: 46201 | I7: 1
A8: TT Renovations | B8: Angelo | C8: Brown | D8: -2468.81 | E8: =VLOOKUP(C8,addresses!B:C,2,FALSE) -> 254 Hampton Dr. | F8: 46208 | H8: 46202 | I8: 4
A9: TT Renovations | B9: Arbour | C9: Arbour | D9: -956.09 | E9: =VLOOKUP(C9,addresses!B:C,2,FALSE) -> 4928 Central Ave. | F9: =VLOOKUP(C9,addresses!B:D,3,FALSE) -> 46205 | H9: 46205 | I9: 41
A10: TT Renovations | B10: Bella | C10: Bella | D10: -379.49 | E10: 3915 Winding Way | F10: 46220 | H10: 46206 | I10: 1
A11: TT Renovations | B11: Basch | C11: Basch | D11: -28468.99 | E11: =VLOOKUP(C11,addresses!B:C,2,FALSE) -> 1135 Ivy Lane | F11: =VLOOKUP(C11,addresses!B:D,3,FALSE) -> 46220 | H11: 46208 | I11: 17
A12: TT Renovations | B12: Baugh | C12: Baugh | D12: -8355.63 | E12: =VLOOKUP(C12,addresses!B:C,2,FALSE) -> 11125 Moss Dr. | F12: =VLOOKUP(C12,addresses!B:D,3,FALSE) -> 46033 | H12: 46220 | I12: 75
A13: TT Renovations | B13: Blueridge | C13: Blueridge | D13: -10677.12 | E13: 119 Blue Ridge Rd | F13: 46208 | H13: 46240 | I13: 2
A14: TT Renovations | B14: Jeff Bontrager | C14: Bontrager | D14: -715.32 | E14: 5734 Ralston Ave | F14: 46220 | H14: 46260 | I14: 6
A15: TT Renovations | B15: Bokelman | C15: Bokelman | D15: -11707.2 | E15: =VLOOKUP(C15,addresses!B:C,2,FALSE) -> 5401 Illinois St. | F15: =VLOOKUP(C15,addresses!B:D,3,FALSE) -> 46220 | H15: 46280 | I15: 1
A16: TT Renovations | B16: Brad Donaldson | C16: Donaldson | D16: -2020.49 | E16: =VLOOKUP(C16,addresses!B:C,2,FALSE) -> 1403 Kessler Blvd E Drive | F16: =VLOOKUP(C16,addresses!B:D,3,FALSE) -> 46220 | H16: Grand Total | I16: 163
A17: TT Renovations | B17: Brar | C17: Brar | D17: -55259.86 | E17: =VLOOKUP(C17,addresses!B:C,2,FALSE) -> 120 Bow Lane St. | F17: =VLOOKUP(C17,addresses!B:D,3,FALSE) -> 46220
A18: TT Renovations | B18: Jody Tetrault | C18: Tetrault | D18: -61510.3 | E18: 5923 Broadway St. | F18: 46220
A19: TT Renovations | B19: Holly Brooks | C19: Brooks | D19: -524.93 | E19: =VLOOKUP(C19,addresses!B:C,2,FALSE) -> #N/A | F19: =VLOOKUP(C19,addresses!B:D,3,FALSE) -> #N/A
A20: TT Renovations | B20: Brigance | C20: Brigance | D20: -14812.63 | E20: =VLOOKUP(C20,addresses!B:C,2,FALSE) -> 8455 Washington Blvd. | F20: =VLOOKUP(C20,addresses!B:D,3,FALSE) -> 46240
A21: TT Renovations | B21: Brim | C21: Brim | D21: -136245.09 | E21: =VLOOKUP(C21,addresses!B:C,2,FALSE) -> 4545 Central Ave | F21: =VLOOKUP(C21,addresses!B:D,3,FALSE) -> 46205
A22: TT Renovations | B22: Buggs.Cheng | C22: Cheng | D22: -599661.58 | E22: 5751 Central Ave. | F22: 46220
A23: TT Renovations | B23: Busto | C23: Busto | D23: -3981.82 | E23: =VLOOKUP(C23,addresses!B:C,2,FALSE) -> 3960 Delaware St. | F23: =VLOOKUP(C23,addresses!B:D,3,FALSE) -> 46202
A24: TT Renovations | B24: CDavis | C24: CDavis | D24: -32162.51 | E24: 1032 Foxglove Circle | F24: 46033
A25: TT Renovations | B25: Central | C25: Central | D25: -50057.63 | E25: 5373 Central Ave. | F25: 46220
A26: TT Renovations | B26: Jason Chappell | C26: Chappel | D26: 190.75 | E26: =VLOOKUP(C26,addresses!B:C,2,FALSE) -> #N/A | F26: =VLOOKUP(C26,addresses!B:D,3,FALSE) -> #N/A
A27: TT Renovations | B27: Christy & Jen | C27: Christy | D27: -397.38 | E27: 326 E 47th St | F27: 46205
A28: TT Renovations | B28: Brian Clay | C28: Clay | E28: 3580 Kessler Blvd East Dr | F28: 46220
A29: TT Renovations | B29: Brian Coles | C29: Coles | E29: 5445 Crestview Dr | F29: 46220
A30: TT Renovations | B30: Colips | C30: Colips | D30: 199.73 | E30: =VLOOKUP(C30,addresses!B:C,2,FALSE) -> #N/A | F30: =VLOOKUP(C30,addresses!B:D,3,FALSE) -> #N/A
A31: TT Renovations | B31: Colleen Brown | C31: Brown | D31: -279265.12 | E31: 254 Hampton Dr. | F31: 46205
A32: TT Renovations | B32: Jennifer Day | C32: Day | D32: 659.44 | E32: =VLOOKUP(C32,addresses!B:C,2,FALSE) -> #N/A | F32: =VLOOKUP(C32,addresses!B:D,3,FALSE) -> #N/A
A33: TT Renovations | B33: DbInteriors | C33: DbInteriors | D33: -3410.8 | E33: 4320 N Meridian St | F33: 46208
A34: TT Renovations | B34: Cornforth | C34: Cornforth | D34: -2182.22 | E34: =VLOOKUP(C34,addresses!B:C,2,FALSE) -> 245 Blue Ridge Rd. | F34: =VLOOKUP(C34,addresses!B:D,3,FALSE) -> 46205
A35: TT Renovations | B35: Cseszko | C35: Cseszko | D35: -7335.39 | E35: =VLOOKUP(C35,addresses!B:C,2,FALSE) -> 4527 Pennsylvania St. | F35: =VLOOKUP(C35,addresses!B:D,3,FALSE) -> 46205
A36: TT Renovations | B36: Damon Lettich | C36: Lettich | D36: -397.05 | E36: =VLOOKUP(C36,addresses!B:C,2,FALSE) -> 4848 Central Ave | F36: =VLOOKUP(C36,addresses!B:D,3,FALSE) -> 46205
A37: TT Renovations | B37: Davey | C37: Davey | D37: -197685.29 | E37: =VLOOKUP(C37,addresses!B:C,2,FALSE) -> 4134 Pennsylvania St | F37: =VLOOKUP(C37,addresses!B:D,3,FALSE) -> 46260
A38: TT Renovations | B38: DePaw | C38: DePaw | D38: 614.41 | E38: =VLOOKUP(C38,addresses!B:C,2,FALSE) -> #N/A | F38: =VLOOKUP(C38,addresses!B:D,3,FALSE) -> #N/A
A39: TT Renovations | B39: Demilt | C39: Demilt | D39: -64481.99 | E39: =VLOOKUP(C39,addresses!B:C,2,FALSE) -> 5520 N Meridian St | F39: =VLOOKUP(C39,addresses!B:D,3,FALSE) -> 46208
A40: TT Renovations | B40: Demotte | C40: Demotte | D40: -80744.33 | E40: =VLOOKUP(C40,addresses!B:C,2,FALSE) -> 5421 N Pennsylvania St. | F40: =VLOOKUP(C40,addresses!B:D,3,FALSE) -> 46220
...

Sheet addresses
A1: Payee | B1: Last Name | C1: Street | D1: Zip | E1: City | F1: State
A2: Mary Ajamie | B2: Ajamie | C2: 4521 Pennsylvania St. | D2: 46205 | E2: Indianapolis | F2: IN
A3: Davina Arbour | B3: Arbour | C3: 4928 Central Ave. | D3: 46205 | E3: Indianapolis | F3: IN
A4: Kim Basch | B4: Basch | C4: 1135 Ivy Lane | D4: 46220 | E4: Indianapolis | F4: IN
A5: Gene & Sharon Baugh | B5: Baugh | C5: 11125 Moss Dr. | D5: 46033 | E5: Carmel | F5: IN
A6: Beau & Kristin Bokelman | B6: Bokelman | C6: 5401 Illinois St. | D6: 46220 | E6: Indianapolis | F6: IN
A7: Aman & Susan Brar | B7: Brar | C7: 120 Bow Lane St. | D7: 46220 | E7: Indianapolis | F7: IN
A8: Steve & Anne Brigance | B8: Brigance | C8: 8455 Washington Blvd. | D8: 46240 | E8: Indianapolis | F8: IN
A9: Nate & Laura Brim | B9: Brim | C9: 4545 Central Ave | D9: 46205 | E9: Indianapolis | F9: IN
A10: Colleen Brown | B10: Brown | C10: 254 Hampton Dr. | D10: 46208 | E10: Indianapolis | F10: IN
A11: Juan & Sheila Brown | B11: Brown | C11: 5740 Central Ave | D11: 46220 | E11: Indianapolis | F11: IN
A12: MaryEllen Brown | B12: Brown | C12: 38 W 59th St | D12: 46208 | E12: Indianapolis | F12: IN
A13: Kathy Busto | B13: Busto | C13: 3960 Delaware St. | D13: 46202 | E13: Indianapolis | F13: IN
... A64: Bill Jones | B64: Jones | C64: 430 N Park Ave | D64: 46202 | E64: Indianapolis | F64: IN
A65: Fran Kandrac | B65: Kandrac
A66: Kevin & Sara Kastner | B66: Kastner | C66: 5135 Central Ave | D66: 46220 | E66: Indianapolis | F66: IN
A67: Jason & Gretchen Katner | B67: Katner | C67: 6215 Central Ave. | D67: 46220 | E67: Indianapolis | F67: IN
A68: Brad & Cassie Kelley | B68: Kelley | C68: 5699 Winthrop Ave | D68: 46220 | E68: Indianapolis | F68: IN
A69: John Vanausdall & Carrie Kirk | B69: Kirk | C69: 4535 N Park Ave | D69: 46205 | E69: Indianapolis | F69: IN
A70: Seth & Amanda Kleiman | B70: Kleiman | C70: 9534 Copley Dr. | D70: 46260 | E70: Indianapolis | F70: IN
A71: John & Rebecca Klein | B71: Klein | C71: 4424 Central Ave | D71: 46205 | E71: Indianapolis | F71: IN
A72: Mike & Michelle Knight | B72: Knight | C72: 121 E 51st St | D72: 46205 | E72: Indianapolis | F72: IN
A73: Dan & Chelsea Koehring | B73: Koehring | C73: 3917 New Jersey St. | D73: 46205 | E73: Indianapolis | F73: IN
A74: Kevin & Mary Beth Kohart | B74: Kohart | C74: 5130 Pennsylvania St. | D74: 46205 | E74: Indianapolis | F74: IN
A75: Bryon & Christine Konvolinka | B75: Konvolinka | C75: 5639 Washington Blvd. | D75: 46220 | E75: Indianapolis | F75: IN
A76: Nick Koon | B76: Koon | C76: 5137 Broadway St | D76: 46205 | E76: Indianapolis | F76: IN
A77: Maggie & Aaron Lasley | B77: Lasley | C77: 1 Stone Wall Ln. | D77: 46077 | E77: Zionsville | F77: IN
... A87: JoAnn Maze | B87: Maze | C87: 5325 N Delaware St | D87: 46220 | E87: Indianapolis | F87: IN
A88: Matt McMichael | B88: McMichael
A89: Jack & Candice Mees | B89: Mees | C89: 4717 Graceland Ave. | D89: 46208 | E89: Indianapolis | F89: IN
A90: Nadine Melind | B90: Melind | C90: 5131 Central Ave. | D90: 46220 | E90: Indianapolis | F90: IN
A91: Joanna & Hap Milliken | B91: Milliken | C91: 412 48th St | D91: 46220 | E91: Indianapolis | F91: IN
A92: Anne Mc Callister Mills | B92: Mills | C92: 6120 N Delaware St. | D92: 46220 | E92: Indianapolis | F92: IN
A93: Phil & Olympia Ming | B93: Ming | C93: 15646 Bridgewater Club Blvd. | D93: 46033 | E93: Carmel | F93: IN
A94: Ray & Dianne Montagno | B94: Montagno | C94: 12276 Charing Cross Rd. | D94: 46033 | E94: Carmel | F94: IN
A95: Gareth & Pam Morgan | B95: Morgan | C95: 4348 48th St. | D95: 46220 | E95: Indianapolis | F95: IN
A96: Ted & Caroline Mosey | B96: Mosey | C96: 4631 N Park Ave | D96: 46205 | E96: Indianapolis | F96: IN
A97: Mike Musson | B97: Musson | C97: 5219 N College Ave | D97: 46205 | E97: Indianapolis | F97: IN
A98: Paul & Michele Musson | B98: Musson | C98: 4545 Delaware St. | D98: 46208 | E98: Indianapolis | F98: In
A99: Paul Musson | B99: Musson | C99: 4545 N Delaware St. | D99: 46205 | E99: Indianapolis | F99: IN
...
